Workbook

Sheet Concentration algale 2026
A1: Ech | B1: Ligne 1 | C1: Ligne 2 | D1: Ligne 3 | E1: Ligne 4 | F1: Ligne 5 | G1: Moyenne algue compté | H1: Nombre de rectangle comptés | I1: Volume de comptage (L) | J1: Facteur de dilution | K1: Nombre d'algue/L | L1: Nombre d'algue/mL | N1: Date | O1: Espèce | P1: n lignes | Q1: µ | R1: Variance | S1: SD | T1: SD % | U1: SEM | V1: SEM %
A2: Chlorella sol 17/02/2026 | B2: 45 | C2: 47 | D2: 34 | E2: 57 | F2: 45 | G2: =AVERAGE(B2:F2) -> 45.6 | H2: 10 | I2: =0.0000001 -> 1e-07 | J2: 2000 | K2: =(G2/I2)*J2 -> 9.12e+11 | L2: =K2/1000 -> 9.12e+08 | N2: 46063 | O2: C. vulgaris | P2: =6 -> 6 | Q2: =AVERAGE(L26:L31) -> 8.5533333e+08 | R2: =_xlfn.VAR.P(L26:L31) -> 5.4475556e+15 | S2: =SQRT(R2) -> 73807558 | T2: =(100*S2/Q2) -> 8.6290987 | U2: =S2/P2 -> 12301260 | V2: =(100*U2/Q2) -> 1.4381831
A3: Chlorella sol 17/02/2026 | B3: 48 | C3: 51 | D3: 56 | E3: 39 | F3: 64 | G3: =AVERAGE(B3:F3) -> 51.6 | H3: 10 | I3: =0.0000001 -> 1e-07 | J3: 2000 | K3: =(G3/I3)*J3 -> 1.032e+12 | L3: =K3/1000 -> 1.032e+09 | N3: 46063 | O3: R. subcapitata | P3: =6 -> 6 | Q3: =AVERAGE(L32:L37) -> 1.9683333e+08 | R3: =_xlfn.VAR.P(L32:L37) -> 1.1680556e+14 | S3: =SQRT(R3) -> 10807662 | T3: =(100*S3/Q3) -> 5.4907681 | U3: =S3/P3 -> 1801277 | V3: =(100*U3/Q3) -> 0.91512802
A4: Chlorella sol 17/02/2026 | B4: 38 | C4: 46 | D4: 50 | E4: 49 | F4: 46 | G4: =AVERAGE(B4:F4) -> 45.8 | H4: 10 | I4: =0.0000001 -> 1e-07 | J4: 2000 | K4: =(G4/I4)*J4 -> 916000000000 | L4: =K4/1000 -> 916000000 | N4: 46070 | O4: C. vulgaris | P4: =6 -> 6 | Q4: =AVERAGE(L2:L7) -> 9.5333333e+08 | R4: =_xlfn.VAR.P(L2:L7) -> 3.6835556e+15 | S4: =SQRT(R4) -> 60692302 | T4: =(100*S4/Q4) -> 6.3663254 | U4: =S4/P4 -> 10115384 | V4: =(100*U4/Q4) -> 1.0610542
A5: Chlorella sol 17/02/2026 | B5: 40 | C5: 55 | D5: 40 | E5: 47 | F5: 36 | G5: =AVERAGE(B5:F5) -> 43.6 | H5: 10 | I5: =0.0000001 -> 1e-07 | J5: 2000 | K5: =(G5/I5)*J5 -> 8.72e+11 | L5: =K5/1000 -> 8.72e+08 | N5: 46070 | O5: R. subcapitata | P5: =6 -> 6 | Q5: =AVERAGE(L8:L13) -> 1.5016667e+08 | R5: =_xlfn.VAR.P(L8:L13) -> 4.4213889e+14 | S5: =SQRT(R5) -> 21027099 | T5: =(100*S5/Q5) -> 14.002508 | U5: =S5/P5 -> 3504516.5 | V5: =(100*U5/Q5) -> 2.3337513
A6: Chlorella sol 17/02/2026 | B6: 51 | C6: 48 | D6: 43 | E6: 58 | F6: 39 | G6: =AVERAGE(B6:F6) -> 47.8 | H6: 10 | I6: =0.0000001 -> 1e-07 | J6: 2000 | K6: =(G6/I6)*J6 -> 956000000000 | L6: =K6/1000 -> 956000000 | N6: 46077 | O6: C. vulgaris | P6: =6 -> 6 | Q6: =AVERAGE(L14:L19) -> 886000000 | R6: =_xlfn.VAR.P(L14:L19) -> 1.1453333e+15 | S6: =SQRT(R6) -> 33842774 | T6: =(100*S6/Q6) -> 3.8197262 | U6: =S6/P6 -> 5640462.3 | V6: =(100*U6/Q6) -> 0.63662103
A7: Chlorella sol 17/02/2026 | B7: 59 | C7: 41 | D7: 44 | E7: 52 | F7: 62 | G7: =AVERAGE(B7:F7) -> 51.6 | H7: 10 | I7: =0.0000001 -> 1e-07 | J7: 2000 | K7: =(G7/I7)*J7 -> 1.032e+12 | L7: =K7/1000 -> 1.032e+09 | N7: 46077 | O7: R. subcapitata | P7: =6 -> 6 | Q7: =AVERAGE(L20:L25) -> 158500000 | R7: =_xlfn.VAR.P(L20:L25) -> 7.2916667e+13 | S7: =SQRT(R7) -> 8539125.6 | T7: =(100*S7/Q7) -> 5.387461 | U7: =S7/P7 -> 1423187.6 | V7: =(100*U7/Q7) -> 0.89791016
A8: Pita sol 17/02/2026 | B8: 46 | C8: 37 | D8: 36 | E8: 40 | F8: 31 | G8: =AVERAGE(B8:F8) -> 38 | H8: 10 | I8: =0.0000001 -> 1e-07 | J8: 500 | K8: =(G8/I8)*J8 -> 190000000000 | L8: =K8/1000 -> 190000000
A9: Pita sol 17/02/2026 | B9: 28 | C9: 39 | D9: 27 | E9: 32 | F9: 36 | G9: =AVERAGE(B9:F9) -> 32.4 | H9: 10 | I9: =0.0000001 -> 1e-07 | J9: 500 | K9: =(G9/I9)*J9 -> 162000000000 | L9: =K9/1000 -> 162000000
A10: Pita sol 17/02/2026 | B10: 46 | C10: 28 | D10: 22 | E10: 17 | F10: 25 | G10: =AVERAGE(B10:F10) -> 27.6 | H10: 10 | I10: =0.0000001 -> 1e-07 | J10: 500 | K10: =(G10/I10)*J10 -> 138000000000 | L10: =K10/1000 -> 138000000
A11: Pita sol 17/02/2026 | B11: 28 | C11: 17 | D11: 25 | E11: 28 | F11: 26 | G11: =AVERAGE(B11:F11) -> 24.8 | H11: 10 | I11: =0.0000001 -> 1e-07 | J11: 500 | K11: =(G11/I11)*J11 -> 1.24e+11 | L11: =K11/1000 -> 1.24e+08
A12: Pita sol 17/02/2026 | B12: 34 | C12: 28 | D12: 24 | E12: 24 | F12: 35 | G12: =AVERAGE(B12:F12) -> 29 | H12: 10 | I12: =0.0000001 -> 1e-07 | J12: 500 | K12: =(G12/I12)*J12 -> 145000000000 | L12: =K12/1000 -> 145000000
A13: Pita sol 17/02/2026 | B13: 21 | C13: 32 | D13: 35 | E13: 31 | F13: 23 | G13: =AVERAGE(B13:F13) -> 28.4 | H13: 10 | I13: =0.0000001 -> 1e-07 | J13: 500 | K13: =(G13/I13)*J13 -> 142000000000 | L13: =K13/1000 -> 142000000
A14: Chlorella sol 24/02/2026 | B14: 51 | C14: 37 | D14: 47 | E14: 49 | F14: 39 | G14: =AVERAGE(B14:F14) -> 44.6 | H14: 10 | I14: =0.0000001 -> 1e-07 | J14: 2000 | K14: =(G14/I14)*J14 -> 8.92e+11 | L14: =K14/1000 -> 8.92e+08
A15: Chlorella sol 24/02/2026 | B15: 42 | C15: 59 | D15: 36 | E15: 33 | F15: 54 | G15: =AVERAGE(B15:F15) -> 44.8 | H15: 10 | I15: =0.0000001 -> 1e-07 | J15: 2000 | K15: =(G15/I15)*J15 -> 896000000000 | L15: =K15/1000 -> 896000000
A16: Chlorella sol 24/02/2026 | B16: 52 | C16: 40 | D16: 47 | E16: 47 | F16: 43 | G16: =AVERAGE(B16:F16) -> 45.8 | H16: 10 | I16: =0.0000001 -> 1e-07 | J16: 2000 | K16: =(G16/I16)*J16 -> 916000000000 | L16: =K16/1000 -> 916000000
A17: Chlorella sol 24/02/2026 | B17: 37 | C17: 40 | D17: 49 | E17: 39 | F17: 39 | G17: =AVERAGE(B17:F17) -> 40.8 | H17: 10 | I17: =0.0000001 -> 1e-07 | J17: 2000 | K17: =(G17/I17)*J17 -> 816000000000 | L17: =K17/1000 -> 816000000
A18: Chlorella sol 24/02/2026 | B18: 46 | C18: 46 | D18: 48 | E18: 35 | F18: 54 | G18: =AVERAGE(B18:F18) -> 45.8 | H18: 10 | I18: =0.0000001 -> 1e-07 | J18: 2000 | K18: =(G18/I18)*J18 -> 916000000000 | L18: =K18/1000 -> 916000000
A19: Chlorella sol 24/02/2026 | B19: 56 | C19: 41 | D19: 38 | E19: 47 | F19: 38 | G19: =AVERAGE(B19:F19) -> 44 | H19: 10 | I19: =0.0000001 -> 1e-07 | J19: 2000 | K19: =(G19/I19)*J19 -> 880000000000 | L19: =K19/1000 -> 880000000
... A37: Pita sol 10/02/2026 | B37: 41 | C37: 35 | D37: 49 | E37: 46 | F37: 38 | G37: =AVERAGE(B37:F37) -> 41.8 | H37: 10 | I37: =0.0000001 -> 1e-07 | J37: 500 | K37: =(G37/I37)*J37 -> 209000000000 | L37: =K37/1000 -> 209000000

Sheet Absorbance
A1: Ech | B1: Date | C1: Espèce | D1: FD | E1: 1/FD | F1: A1 | G1: A2 | H1: A3 | I1: Aµ | J1: A var | K1: A SD | L1: A SEM | M1: Cµ | N1: C SEM | O1: Cµ avec FD | P1: C SEM avec FD
A2: Chlorella sol 17/02/2026 | B2: 46070 | C2: Chlorella | D2: =3000/100 -> 30 | E2: =1/D2 -> 0.033333333 | F2: 1.409 | G2: NA | H2: NA | I2: =AVERAGE(F2:H2) -> 1.409 | J2: =_xlfn.VAR.P(F2:H2) -> 0 | K2: =SQRT(J2) -> 0 | L2: =K2/SQRT(COUNT(F2:H2)) -> 0 | M2: ='Concentration algale 2026'!Q$4 -> 9.5333333e+08 | N2: ='Concentration algale 2026'!U$4 -> 10115384 | O2: =M2*E2 -> 31777778 | P2: =N2*E2 -> 337179.46
A3: Chlorella sol 17/02/2026 | B3: 46070 | C3: Chlorella | D3: =3000/75 -> 40 | E3: =1/D3 -> 0.025 | F3: 1.074 | G3: 1.074 | H3: 1.064 | I3: =AVERAGE(F3:H3) -> 1.0706667 | J3: =_xlfn.VAR.P(F3:H3) -> 2.2222222e-05 | K3: =SQRT(J3) -> 0.0047140452 | L3: =K3/SQRT(COUNT(F3:H3)) -> 0.0027216553 | M3: ='Concentration algale 2026'!Q$4 -> 9.5333333e+08 | N3: ='Concentration algale 2026'!U$4 -> 10115384 | O3: =M3*E3 -> 23833333 | P3: =N3*E3 -> 252884.59
A4: Chlorella sol 17/02/2026 | B4: 46070 | C4: Chlorella | D4: =3000/50 -> 60 | E4: =1/D4 -> 0.016666667 | F4: 0.753 | G4: 0.755 | H4: 0.755 | I4: =AVERAGE(F4:H4) -> 0.75433333 | J4: =_xlfn.VAR.P(F4:H4) -> 8.8888889e-07 | K4: =SQRT(J4) -> 0.00094280904 | L4: =K4/SQRT(COUNT(F4:H4)) -> 0.00054433105 | M4: ='Concentration algale 2026'!Q$4 -> 9.5333333e+08 | N4: ='Concentration algale 2026'!U$4 -> 10115384 | O4: =M4*E4 -> 15888889 | P4: =N4*E4 -> 168589.73
A5: Chlorella sol 17/02/2026 | B5: 46070 | C5: Chlorella | D5: =3000/37.5 -> 80 | E5: =1/D5 -> 0.0125 | F5: 0.564 | G5: 0.548 | H5: 0.545 | I5: =AVERAGE(F5:H5) -> 0.55233333 | J5: =_xlfn.VAR.P(F5:H5) -> 6.9555556e-05 | K5: =SQRT(J5) -> 0.0083399973 | L5: =K5/SQRT(COUNT(F5:H5)) -> 0.0048150997 | M5: ='Concentration algale 2026'!Q$4 -> 9.5333333e+08 | N5: ='Concentration algale 2026'!U$4 -> 10115384 | O5: =M5*E5 -> 11916667 | P5: =N5*E5 -> 126442.3
A6: Chlorella sol 17/02/2026 | B6: 46070 | C6: Chlorella | D6: =3000/25 -> 120 | E6: =1/D6 -> 0.0083333333 | F6: 0.385 | G6: 0.385 | H6: 0.389 | I6: =AVERAGE(F6:H6) -> 0.38633333 | J6: =_xlfn.VAR.P(F6:H6) -> 3.5555556e-06 | K6: =SQRT(J6) -> 0.0018856181 | L6: =K6/SQRT(COUNT(F6:H6)) -> 0.0010886621 | M6: ='Concentration algale 2026'!Q$4 -> 9.5333333e+08 | N6: ='Concentration algale 2026'!U$4 -> 10115384 | O6: =M6*E6 -> 7944444.4 | P6: =N6*E6 -> 84294.864
A7: Chlorella sol 17/02/2026 | B7: 46070 | C7: Chlorella | D7: =3000/17.5 -> 171.42857 | E7: =1/D7 -> 0.0058333333 | F7: 0.281 | G7: 0.274 | H7: 0.275 | I7: =AVERAGE(F7:H7) -> 0.27666667 | J7: =_xlfn.VAR.P(F7:H7) -> 9.5555556e-06 | K7: =SQRT(J7) -> 0.0030912062 | L7: =K7/SQRT(COUNT(F7:H7)) -> 0.0017847087 | M7: ='Concentration algale 2026'!Q$4 -> 9.5333333e+08 | N7: ='Concentration algale 2026'!U$4 -> 10115384 | O7: =M7*E7 -> 5561111.1 | P7: =N7*E7 -> 59006.405
A8: Chlorella sol 17/02/2026 | B8: 46070 | C8: Chlorella | D8: =3000/10 -> 300 | E8: =1/D8 -> 0.0033333333 | F8: 0.164 | G8: 0.155 | H8: 0.164 | I8: =AVERAGE(F8:H8) -> 0.161 | J8: =_xlfn.VAR.P(F8:H8) -> 1.8e-05 | K8: =SQRT(J8) -> 0.0042426407 | L8: =K8/SQRT(COUNT(F8:H8)) -> 0.0024494897 | M8: ='Concentration algale 2026'!Q$4 -> 9.5333333e+08 | N8: ='Concentration algale 2026'!U$4 -> 10115384 | O8: =M8*E8 -> 3177777.8 | P8: =N8*E8 -> 33717.946
A9: Chlorella sol 17/02/2026 | B9: 46070 | C9: Chlorella | D9: =3000/5 -> 600 | E9: =1/D9 -> 0.0016666667 | F9: 0.083 | G9: 0.086 | H9: 0.082 | I9: =AVERAGE(F9:H9) -> 0.083666667 | J9: =_xlfn.VAR.P(F9:H9) -> 2.8888889e-06 | K9: =SQRT(J9) -> 0.0016996732 | L9: =K9/SQRT(COUNT(F9:H9)) -> 0.00098130676 | M9: ='Concentration algale 2026'!Q$4 -> 9.5333333e+08 | N9: ='Concentration algale 2026'!U$4 -> 10115384 | O9: =M9*E9 -> 1588888.9 | P9: =N9*E9 -> 16858.973
A10: Pita sol 17/02/2026 | B10: 46070 | C10: Pita | D10: =3000/300 -> 10 | E10: =1/D10 -> 0.1 | F10: 1.178 | G10: 1.179 | H10: 1.184 | I10: =AVERAGE(F10:H10) -> 1.1803333 | J10: =_xlfn.VAR.P(F10:H10) -> 6.8888889e-06 | K10: =SQRT(J10) -> 0.0026246693 | L10: =K10/SQRT(COUNT(F10:H10)) -> 0.0015153535 | M10: ='Concentration algale 2026'!Q$5 -> 1.5016667e+08 | N10: ='Concentration algale 2026'!U$5 -> 3504516.5 | O10: =M10*E10 -> 15016667 | P10: =N10*E10 -> 350451.65
A11: Pita sol 17/02/2026 | B11: 46070 | C11: Pita | D11: =3000/250 -> 12 | E11: =1/D11 -> 0.083333333 | F11: =1.028 -> 1.028 | G11: 0.994 | H11: 1.002 | I11: =AVERAGE(F11:H11) -> 1.008 | J11: =_xlfn.VAR.P(F11:H11) -> 0.00021066667 | K11: =SQRT(J11) -> 0.014514361 | L11: =K11/SQRT(COUNT(F11:H11)) -> 0.0083798701 | M11: ='Concentration algale 2026'!Q$5 -> 1.5016667e+08 | N11: ='Concentration algale 2026'!U$5 -> 3504516.5 | O11: =M11*E11 -> 12513889 | P11: =N11*E11 -> 292043.04
A12: Pita sol 17/02/2026 | B12: 46070 | C12: Pita | D12: =3000/200 -> 15 | E12: =1/D12 -> 0.066666667 | F12: 0.821 | G12: 0.774 | H12: 0.763 | I12: =AVERAGE(F12:H12) -> 0.786 | J12: =_xlfn.VAR.P(F12:H12) -> 0.00063266667 | K12: =SQRT(J12) -> 0.025152866 | L12: =K12/SQRT(COUNT(F12:H12)) -> 0.014522014 | M12: ='Concentration algale 2026'!Q$5 -> 1.5016667e+08 | N12: ='Concentration algale 2026'!U$5 -> 3504516.5 | O12: =M12*E12 -> 10011111 | P12: =N12*E12 -> 233634.43
A13: Pita sol 17/02/2026 | B13: 46070 | C13: Pita | D13: =3000/150 -> 20 | E13: =1/D13 -> 0.05 | F13: 0.681 | G13: 0.634 | H13: 0.609 | I13: =AVERAGE(F13:H13) -> 0.64133333 | J13: =_xlfn.VAR.P(F13:H13) -> 0.00089088889 | K13: =SQRT(J13) -> 0.029847762 | L13: =K13/SQRT(COUNT(F13:H13)) -> 0.017232613 | M13: ='Concentration algale 2026'!Q$5 -> 1.5016667e+08 | N13: ='Concentration algale 2026'!U$5 -> 3504516.5 | O13: =M13*E13 -> 7508333.3 | P13: =N13*E13 -> 175225.82
A14: Pita sol 17/02/2026 | B14: 46070 | C14: Pita | D14: =3000/100 -> 30 | E14: =1/D14 -> 0.033333333 | F14: 0.434 | G14: 0.444 | H14: 0.446 | I14: =AVERAGE(F14:H14) -> 0.44133333 | J14: =_xlfn.VAR.P(F14:H14) -> 2.7555556e-05 | K14: =SQRT(J14) -> 0.0052493386 | L14: =K14/SQRT(COUNT(F14:H14)) -> 0.003030707 | M14: ='Concentration algale 2026'!Q$5 -> 1.5016667e+08 | N14: ='Concentration algale 2026'!U$5 -> 3504516.5 | O14: =M14*E14 -> 5005555.6 | P14: =N14*E14 -> 116817.22
A15: Pita sol 17/02/2026 | B15: 46070 | C15: Pita | D15: =3000/50 -> 60 | E15: =1/D15 -> 0.016666667 | F15: 0.216 | G15: 0.221 | H15: 0.22 | I15: =AVERAGE(F15:H15) -> 0.219 | J15: =_xlfn.VAR.P(F15:H15) -> 4.6666667e-06 | K15: =SQRT(J15) -> 0.0021602469 | L15: =K15/SQRT(COUNT(F15:H15)) -> 0.0012472191 | M15: ='Concentration algale 2026'!Q$5 -> 1.5016667e+08 | N15: ='Concentration algale 2026'!U$5 -> 3504516.5 | O15: =M15*E15 -> 2502777.8 | P15: =N15*E15 -> 58408.608
A16: Pita sol 17/02/2026 | B16: 46070 | C16: Pita | D16: =3000/25 -> 120 | E16: =1/D16 -> 0.0083333333 | F16: 0.111 | G16: 0.115 | H16: 0.111 | I16: =AVERAGE(F16:H16) -> 0.11233333 | J16: =_xlfn.VAR.P(F16:H16) -> 3.5555556e-06 | K16: =SQRT(J16) -> 0.0018856181 | L16: =K16/SQRT(COUNT(F16:H16)) -> 0.0010886621 | M16: ='Concentration algale 2026'!Q$5 -> 1.5016667e+08 | N16: ='Concentration algale 2026'!U$5 -> 3504516.5 | O16: =M16*E16 -> 1251388.9 | P16: =N16*E16 -> 29204.304
A17: Chlorella sol 24/02/2026 | B17: 46077 | C17: Chlorella | D17: =3000/100 -> 30 | E17: =1/D17 -> 0.033333333 | F17: 1.406 | G17: 1.377 | H17: 1.37 | I17: =AVERAGE(F17:H17) -> 1.3843333 | J17: =_xlfn.VAR.P(F17:H17) -> 0.00024288889 | K17: =SQRT(J17) -> 0.015584893 | L17: =K17/SQRT(COUNT(F17:H17)) -> 0.0089979422 | M17: ='Concentration algale 2026'!Q$6 -> 886000000 | N17: ='Concentration algale 2026'!U$6 -> 5640462.3 | O17: =M17*E17 -> 29533333 | P17: =N17*E17 -> 188015.41
A18: Chlorella sol 24/02/2026 | B18: 46077 | C18: Chlorella | D18: =3000/75 -> 40 | E18: =1/D18 -> 0.025 | F18: 1.061 | G18: 1.032 | H18: 1.051 | I18: =AVERAGE(F18:H18) -> 1.048 | J18: =_xlfn.VAR.P(F18:H18) -> 0.00014466667 | K18: =SQRT(J18) -> 0.012027746 | L18: =K18/SQRT(COUNT(F18:H18)) -> 0.0069442222 | M18: ='Concentration algale 2026'!Q$6 -> 886000000 | N18: ='Concentration algale 2026'!U$6 -> 5640462.3 | O18: =M18*E18 -> 22150000 | P18: =N18*E18 -> 141011.56
A19: Chlorella sol 24/02/2026 | B19: 46077 | C19: Chlorella | D19: =3000/50 -> 60 | E19: =1/D19 -> 0.016666667 | F19: 0.737 | G19: 0.732 | H19: 0.72 | I19: =AVERAGE(F19:H19) -> 0.72966667 | J19: =_xlfn.VAR.P(F19:H19) -> 5.0888889e-05 | K19: =SQRT(J19) -> 0.0071336449 | L19: =K19/SQRT(COUNT(F19:H19)) -> 0.0041186118 | M19: ='Concentration algale 2026'!Q$6 -> 886000000 | N19: ='Concentration algale 2026'!U$6 -> 5640462.3 | O19: =M19*E19 -> 14766667 | P19: =N19*E19 -> 94007.705
A20: Chlorella sol 24/02/2026 | B20: 46077 | C20: Chlorella | D20: =3000/37.5 -> 80 | E20: =1/D20 -> 0.0125 | F20: 0.558 | G20: 0.5 | H20: 0.502 | I20: =AVERAGE(F20:H20) -> 0.52 | J20: =_xlfn.VAR.P(F20:H20) -> 0.00072266667 | K20: =SQRT(J20) -> 0.02688246 | L20: =K20/SQRT(COUNT(F20:H20)) -> 0.015520596 | M20: ='Concentration algale 2026'!Q$6 -> 886000000 | N20: ='Concentration algale 2026'!U$6 -> 5640462.3 | O20: =M20*E20 -> 11075000 | P20: =N20*E20 -> 70505.779
A21: Chlorella sol 24/02/2026 | B21: 46077 | C21: Chlorella | D21: =3000/25 -> 120 | E21: =1/D21 -> 0.0083333333 | F21: 0.377 | G21: 0.33 | H21: 0.361 | I21: =AVERAGE(F21:H21) -> 0.356 | J21: =_xlfn.VAR.P(F21:H21) -> 0.00038066667 | K21: =SQRT(J21) -> 0.019510681 | L21: =K21/SQRT(COUNT(F21:H21)) -> 0.011264497 | M21: ='Concentration algale 2026'!Q$6 -> 886000000 | N21: ='Concentration algale 2026'!U$6 -> 5640462.3 | O21: =M21*E21 -> 7383333.3 | P21: =N21*E21 -> 47003.852
A22: Chlorella sol 24/02/2026 | B22: 46077 | C22: Chlorella | D22: =3000/17.5 -> 171.42857 | E22: =1/D22 -> 0.0058333333 | F22: 0.271 | G22: 0.261 | H22: 0.264 | I22: =AVERAGE(F22:H22) -> 0.26533333 | J22: =_xlfn.VAR.P(F22:H22) -> 1.7555556e-05 | K22: =SQRT(J22) -> 0.004189935 | L22: =K22/SQRT(COUNT(F22:H22)) -> 0.0024190601 | M22: ='Concentration algale 2026'!Q$6 -> 886000000 | N22: ='Concentration algale 2026'!U$6 -> 5640462.3 | O22: =M22*E22 -> 5168333.3 | P22: =N22*E22 -> 32902.697
A23: Chlorella sol 24/02/2026 | B23: 46077 | C23: Chlorella | D23: =3000/10 -> 300 | E23: =1/D23 -> 0.0033333333 | F23: 0.126 | G23: 0.183 | H23: 0.157 | I23: =AVERAGE(F23:H23) -> 0.15533333 | J23: =_xlfn.VAR.P(F23:H23) -> 0.00054288889 | K23: =SQRT(J23) -> 0.023299976 | L23: =K23/SQRT(COUNT(F23:H23)) -> 0.013452248 | M23: ='Concentration algale 2026'!Q$6 -> 886000000 | N23: ='Concentration algale 2026'!U$6 -> 5640462.3 | O23: =M23*E23 -> 2953333.3 | P23: =N23*E23 -> 18801.541
A24: Chlorella sol 24/02/2026 | B24: 46077 | C24: Chlorella | D24: =3000/5 -> 600 | E24: =1/D24 -> 0.0016666667 | F24: 0.095 | G24: 0.083 | H24: 0.074 | I24: =AVERAGE(F24:H24) -> 0.084 | J24: =_xlfn.VAR.P(F24:H24) -> 7.4e-05 | K24: =SQRT(J24) -> 0.0086023253 | L24: =K24/SQRT(COUNT(F24:H24)) -> 0.0049665548 | M24: ='Concentration algale 2026'!Q$6 -> 886000000 | N24: ='Concentration algale 2026'!U$6 -> 5640462.3 | O24: =M24*E24 -> 1476666.7 | P24: =N24*E24 -> 9400.7705
A25: Pita sol 24/02/2026 | B25: 46077 | C25: Pita | D25: =3000/300 -> 10 | E25: =1/D25 -> 0.1 | F25: 1.24 | G25: 1.191 | H25: 1.196 | I25: =AVERAGE(F25:H25) -> 1.209 | J25: =_xlfn.VAR.P(F25:H25) -> 0.00048466667 | K25: =SQRT(J25) -> 0.022015146 | L25: =K25/SQRT(COUNT(F25:H25)) -> 0.012710451 | M25: ='Concentration algale 2026'!Q$7 -> 158500000 | N25: ='Concentration algale 2026'!U$7 -> 1423187.6 | O25: =M25*E25 -> 15850000 | P25: =N25*E25 -> 142318.76
A26: Pita sol 24/02/2026 | B26: 46077 | C26: Pita | D26: =3000/250 -> 12 | E26: =1/D26 -> 0.083333333 | F26: =1.019 -> 1.019 | G26: 1.064 | H26: 1.051 | I26: =AVERAGE(F26:H26) -> 1.0446667 | J26: =_xlfn.VAR.P(F26:H26) -> 0.00035755556 | K26: =SQRT(J26) -> 0.018909139 | L26: =K26/SQRT(COUNT(F26:H26)) -> 0.010917197 | M26: ='Concentration algale 2026'!Q$7 -> 158500000 | N26: ='Concentration algale 2026'!U$7 -> 1423187.6 | O26: =M26*E26 -> 13208333 | P26: =N26*E26 -> 118598.97
A27: Pita sol 24/02/2026 | B27: 46077 | C27: Pita | D27: =3000/200 -> 15 | E27: =1/D27 -> 0.066666667 | F27: 0.86 | G27: 0.865 | H27: 0.871 | I27: =AVERAGE(F27:H27) -> 0.86533333 | J27: =_xlfn.VAR.P(F27:H27) -> 2.0222222e-05 | K27: =SQRT(J27) -> 0.0044969125 | L27: =K27/SQRT(COUNT(F27:H27)) -> 0.0025962937 | M27: ='Concentration algale 2026'!Q$7 -> 158500000 | N27: ='Concentration algale 2026'!U$7 -> 1423187.6 | O27: =M27*E27 -> 10566667 | P27: =N27*E27 -> 94879.174
A28: Pita sol 24/02/2026 | B28: 46077 | C28: Pita | D28: =3000/150 -> 20 | E28: =1/D28 -> 0.05 | F28: 0.674 | G28: 0.647 | H28: 0.653 | I28: =AVERAGE(F28:H28) -> 0.658 | J28: =_xlfn.VAR.P(F28:H28) -> 0.000134 | K28: =SQRT(J28) -> 0.011575837 | L28: =K28/SQRT(COUNT(F28:H28)) -> 0.0066833126 | M28: ='Concentration algale 2026'!Q$7 -> 158500000 | N28: ='Concentration algale 2026'!U$7 -> 1423187.6 | O28: =M28*E28 -> 7925000 | P28: =N28*E28 -> 71159.38
A29: Pita sol 24/02/2026 | B29: 46077 | C29: Pita | D29: =3000/100 -> 30 | E29: =1/D29 -> 0.033333333 | F29: 0.449 | G29: 0.437 | H29: 0.438 | I29: =AVERAGE(F29:H29) -> 0.44133333 | J29: =_xlfn.VAR.P(F29:H29) -> 2.9555556e-05 | K29: =SQRT(J29) -> 0.0054365021 | L29: =K29/SQRT(COUNT(F29:H29)) -> 0.003138766 | M29: ='Concentration algale 2026'!Q$7 -> 158500000 | N29: ='Concentration algale 2026'!U$7 -> 1423187.6 | O29: =M29*E29 -> 5283333.3 | P29: =N29*E29 -> 47439.587
A30: Pita sol 24/02/2026 | B30: 46077 | C30: Pita | D30: =3000/50 -> 60 | E30: =1/D30 -> 0.016666667 | F30: 0.231 | G30: 0.22 | H30: 0.219 | I30: =AVERAGE(F30:H30) -> 0.22333333 | J30: =_xlfn.VAR.P(F30:H30) -> 2.9555556e-05 | K30: =SQRT(J30) -> 0.0054365021 | L30: =K30/SQRT(COUNT(F30:H30)) -> 0.003138766 | M30: ='Concentration algale 2026'!Q$7 -> 158500000 | N30: ='Concentration algale 2026'!U$7 -> 1423187.6 | O30: =M30*E30 -> 2641666.7 | P30: =N30*E30 -> 23719.793
A31: Pita sol 24/02/2026 | B31: 46077 | C31: Pita | D31: =3000/25 -> 120 | E31: =1/D31 -> 0.0083333333 | F31: 0.121 | G31: 0.105 | H31: 0.111 | I31: =AVERAGE(F31:H31) -> 0.11233333 | J31: =_xlfn.VAR.P(F31:H31) -> 4.3555556e-05 | K31: =SQRT(J31) -> 0.0065996633 | L31: =K31/SQRT(COUNT(F31:H31)) -> 0.0038103174 | M31: ='Concentration algale 2026'!$Q$7 -> 158500000 | N31: ='Concentration algale 2026'!U$7 -> 1423187.6 | O31: =M31*E31 -> 1320833.3 | P31: =N31*E31 -> 11859.897
A32: Chlorella sol 10/02/2026 | B32: 46063 | C32: Chlorella | D32: =3000/100 -> 30 | E32: =1/D32 -> 0.033333333 | F32: 1.105 | G32: 1.021 | H32: 1.049 | I32: =AVERAGE(F32:H32) -> 1.0583333 | J32: =_xlfn.VAR.P(F32:H32) -> 0.0012195556 | K32: =SQRT(J32) -> 0.034922136 | L32: =K32/SQRT(COUNT(F32:H32)) -> 0.020162304 | M32: ='Concentration algale 2026'!Q$2 -> 8.5533333e+08 | N32: ='Concentration algale 2026'!U$2 -> 12301260 | O32: =M32*E32 -> 28511111 | P32: =N32*E32 -> 410041.99
A33: Chlorella sol 10/02/2026 | B33: 46063 | C33: Chlorella | D33: =3000/75 -> 40 | E33: =1/D33 -> 0.025 | F33: 0.829 | G33: 0.847 | H33: 0.875 | I33: =AVERAGE(F33:H33) -> 0.85033333 | J33: =_xlfn.VAR.P(F33:H33) -> 0.00035822222 | K33: =SQRT(J33) -> 0.018926759 | L33: =K33/SQRT(COUNT(F33:H33)) -> 0.01092737 | M33: ='Concentration algale 2026'!Q$2 -> 8.5533333e+08 | N33: ='Concentration algale 2026'!U$2 -> 12301260 | O33: =M33*E33 -> 21383333 | P33: =N33*E33 -> 307531.49
A34: Chlorella sol 10/02/2026 | B34: 46063 | C34: Chlorella | D34: =3000/50 -> 60 | E34: =1/D34 -> 0.016666667 | F34: 0.601 | G34: 0.586 | H34: 0.554 | I34: =AVERAGE(F34:H34) -> 0.58033333 | J34: =_xlfn.VAR.P(F34:H34) -> 0.00038422222 | K34: =SQRT(J34) -> 0.019601587 | L34: =K34/SQRT(COUNT(F34:H34)) -> 0.011316982 | M34: ='Concentration algale 2026'!Q$2 -> 8.5533333e+08 | N34: ='Concentration algale 2026'!U$2 -> 12301260 | O34: =M34*E34 -> 14255556 | P34: =N34*E34 -> 205020.99
A35: Chlorella sol 10/02/2026 | B35: 46063 | C35: Chlorella | D35: =3000/37.5 -> 80 | E35: =1/D35 -> 0.0125 | F35: 0.452 | G35: 0.416 | H35: 0.432 | I35: =AVERAGE(F35:H35) -> 0.43333333 | J35: =_xlfn.VAR.P(F35:H35) -> 0.00021688889 | K35: =SQRT(J35) -> 0.014727148 | L35: =K35/SQRT(COUNT(F35:H35)) -> 0.0085027229 | M35: ='Concentration algale 2026'!Q$2 -> 8.5533333e+08 | N35: ='Concentration algale 2026'!U$2 -> 12301260 | O35: =M35*E35 -> 10691667 | P35: =N35*E35 -> 153765.74
A36: Chlorella sol 10/02/2026 | B36: 46063 | C36: Chlorella | D36: =3000/25 -> 120 | E36: =1/D36 -> 0.0083333333 | F36: 0.313 | G36: 0.305 | H36: 0.32 | I36: =AVERAGE(F36:H36) -> 0.31266667 | J36: =_xlfn.VAR.P(F36:H36) -> 3.7555556e-05 | K36: =SQRT(J36) -> 0.0061282588 | L36: =K36/SQRT(COUNT(F36:H36)) -> 0.0035381519 | M36: ='Concentration algale 2026'!Q$2 -> 8.5533333e+08 | N36: ='Concentration algale 2026'!U$2 -> 12301260 | O36: =M36*E36 -> 7127777.8 | P36: =N36*E36 -> 102510.5
A37: Chlorella sol 10/02/2026 | B37: 46063 | C37: Chlorella | D37: =3000/17.5 -> 171.42857 | E37: =1/D37 -> 0.0058333333 | F37: 0.2 | G37: 0.203 | H37: 0.22 | I37: =AVERAGE(F37:H37) -> 0.20766667 | J37: =_xlfn.VAR.P(F37:H37) -> 7.7555556e-05 | K37: =SQRT(J37) -> 0.0088065632 | L37: =K37/SQRT(COUNT(F37:H37)) -> 0.0050844716 | M37: ='Concentration algale 2026'!Q$2 -> 8.5533333e+08 | N37: ='Concentration algale 2026'!U$2 -> 12301260 | O37: =M37*E37 -> 4989444.4 | P37: =N37*E37 -> 71757.348
A38: Chlorella sol 10/02/2026 | B38: 46063 | C38: Chlorella | D38: =3000/10 -> 300 | E38: =1/D38 -> 0.0033333333 | F38: 0.152 | G38: 0.136 | H38: 0.12 | I38: =AVERAGE(F38:H38) -> 0.136 | J38: =_xlfn.VAR.P(F38:H38) -> 0.00017066667 | K38: =SQRT(J38) -> 0.013063945 | L38: =K38/SQRT(COUNT(F38:H38)) -> 0.0075424723 | M38: ='Concentration algale 2026'!Q$2 -> 8.5533333e+08 | N38: ='Concentration algale 2026'!U$2 -> 12301260 | O38: =M38*E38 -> 2851111.1 | P38: =N38*E38 -> 41004.199
A39: Chlorella sol 10/02/2026 | B39: 46063 | C39: Chlorella | D39: =3000/5 -> 600 | E39: =1/D39 -> 0.0016666667 | F39: 0.07 | G39: 0.046 | H39: 0.054 | I39: =AVERAGE(F39:H39) -> 0.056666667 | J39: =_xlfn.VAR.P(F39:H39) -> 9.9555556e-05 | K39: =SQRT(J39) -> 0.009977753 | L39: =K39/SQRT(COUNT(F39:H39)) -> 0.0057606584 | M39: ='Concentration algale 2026'!Q$2 -> 8.5533333e+08 | N39: ='Concentration algale 2026'!U$2 -> 12301260 | O39: =M39*E39 -> 1425555.6 | P39: =N39*E39 -> 20502.099
A40: Pita sol 10/02/2026 | B40: 46063 | C40: Pita | D40: =3000/300 -> 10 | E40: =1/D40 -> 0.1 | F40: 1.392 | G40: 1.382 | H40: 1.334 | I40: =AVERAGE(F40:H40) -> 1.3693333 | J40: =_xlfn.VAR.P(F40:H40) -> 0.00064088889 | K40: =SQRT(J40) -> 0.025315783 | L40: =K40/SQRT(COUNT(F40:H40)) -> 0.014616074 | M40: ='Concentration algale 2026'!Q$3 -> 1.9683333e+08 | N40: ='Concentration algale 2026'!U$3 -> 1801277 | O40: =M40*E40 -> 19683333 | P40: =N40*E40 -> 180127.7
...
